2025-05-23 13:15:31,858 [INFO] [root] Logging configurado. Archivo de log: logs\2025-05-23\2025-05-23_13-15-31.log
2025-05-23 13:15:31,974 [ERROR] [loader] Error de conexi√≥n con el servidor
Traceback (most recent call last):
  File "C:\Users\CASTILLOEMILYGABRIEL\OneDrive - TK Elevator\Documentos\chatbot_evaluation\evaluation\Lib\site-packages\urllib3\connection.py", line 198, in _new_conn
    sock = connection.create_connection(
        (self._dns_host, self.port),
    ...<2 lines>...
        socket_options=self.socket_options,
    )
  File "C:\Users\CASTILLOEMILYGABRIEL\OneDrive - TK Elevator\Documentos\chatbot_evaluation\evaluation\Lib\site-packages\urllib3\util\connection.py", line 60, in create_connection
    for res in socket.getaddrinfo(host, port, family, socket.SOCK_STREAM):
               ~~~~~~~~~~~~~~~~~~^^^^^^^^^^^^^^^^^^^^^^^^^^^^^^^^^^^^^^^^
  File "C:\Users\CASTILLOEMILYGABRIEL\AppData\Local\Programs\Python\Python313\Lib\socket.py", line 977, in getaddrinfo
    for res in _socket.getaddrinfo(host, port, family, type, proto, flags):
               ~~~~~~~~~~~~~~~~~~~^^^^^^^^^^^^^^^^^^^^^^^^^^^^^^^^^^^^^^^^
socket.gaierror: [Errno 11001] getaddrinfo failed

The above exception was the direct cause of the following exception:

Traceback (most recent call last):
  File "C:\Users\CASTILLOEMILYGABRIEL\OneDrive - TK Elevator\Documentos\chatbot_evaluation\evaluation\Lib\site-packages\urllib3\connectionpool.py", line 787, in urlopen
    response = self._make_request(
        conn,
    ...<10 lines>...
        **response_kw,
    )
  File "C:\Users\CASTILLOEMILYGABRIEL\OneDrive - TK Elevator\Documentos\chatbot_evaluation\evaluation\Lib\site-packages\urllib3\connectionpool.py", line 488, in _make_request
    raise new_e
  File "C:\Users\CASTILLOEMILYGABRIEL\OneDrive - TK Elevator\Documentos\chatbot_evaluation\evaluation\Lib\site-packages\urllib3\connectionpool.py", line 464, in _make_request
    self._validate_conn(conn)
    ~~~~~~~~~~~~~~~~~~~^^^^^^
  File "C:\Users\CASTILLOEMILYGABRIEL\OneDrive - TK Elevator\Documentos\chatbot_evaluation\evaluation\Lib\site-packages\urllib3\connectionpool.py", line 1093, in _validate_conn
    conn.connect()
    ~~~~~~~~~~~~^^
  File "C:\Users\CASTILLOEMILYGABRIEL\OneDrive - TK Elevator\Documentos\chatbot_evaluation\evaluation\Lib\site-packages\urllib3\connection.py", line 704, in connect
    self.sock = sock = self._new_conn()
                       ~~~~~~~~~~~~~~^^
  File "C:\Users\CASTILLOEMILYGABRIEL\OneDrive - TK Elevator\Documentos\chatbot_evaluation\evaluation\Lib\site-packages\urllib3\connection.py", line 205, in _new_conn
    raise NameResolutionError(self.host, self, e) from e
urllib3.exceptions.NameResolutionError: <urllib3.connection.HTTPSConnection object at 0x0000020ED8A87A10>: Failed to resolve 'tu-api-url.com' ([Errno 11001] getaddrinfo failed)

The above exception was the direct cause of the following exception:

Traceback (most recent call last):
  File "C:\Users\CASTILLOEMILYGABRIEL\OneDrive - TK Elevator\Documentos\chatbot_evaluation\evaluation\Lib\site-packages\requests\adapters.py", line 667, in send
    resp = conn.urlopen(
        method=request.method,
    ...<9 lines>...
        chunked=chunked,
    )
  File "C:\Users\CASTILLOEMILYGABRIEL\OneDrive - TK Elevator\Documentos\chatbot_evaluation\evaluation\Lib\site-packages\urllib3\connectionpool.py", line 841, in urlopen
    retries = retries.increment(
        method, url, error=new_e, _pool=self, _stacktrace=sys.exc_info()[2]
    )
  File "C:\Users\CASTILLOEMILYGABRIEL\OneDrive - TK Elevator\Documentos\chatbot_evaluation\evaluation\Lib\site-packages\urllib3\util\retry.py", line 519, in increment
    raise MaxRetryError(_pool, url, reason) from reason  # type: ignore[arg-type]
    ^^^^^^^^^^^^^^^^^^^^^^^^^^^^^^^^^^^^^^^^^^^^^^^^^^^
urllib3.exceptions.MaxRetryError: HTTPSConnectionPool(host='tu-api-url.com', port=443): Max retries exceeded with url: /endpoint (Caused by NameResolutionError("<urllib3.connection.HTTPSConnection object at 0x0000020ED8A87A10>: Failed to resolve 'tu-api-url.com' ([Errno 11001] getaddrinfo failed)"))

During handling of the above exception, another exception occurred:

Traceback (most recent call last):
  File "c:\Users\CASTILLOEMILYGABRIEL\OneDrive - TK Elevator\Documentos\chatbot_evaluation\utils\loader.py", line 42, in send_question_to_target
    response = requests.post(url, headers=headers, json=body, cookies=session_cookies, verify=False)
  File "C:\Users\CASTILLOEMILYGABRIEL\OneDrive - TK Elevator\Documentos\chatbot_evaluation\evaluation\Lib\site-packages\requests\api.py", line 115, in post
    return request("post", url, data=data, json=json, **kwargs)
  File "C:\Users\CASTILLOEMILYGABRIEL\OneDrive - TK Elevator\Documentos\chatbot_evaluation\evaluation\Lib\site-packages\requests\api.py", line 59, in request
    return session.request(method=method, url=url, **kwargs)
           ~~~~~~~~~~~~~~~^^^^^^^^^^^^^^^^^^^^^^^^^^^^^^^^^^
  File "C:\Users\CASTILLOEMILYGABRIEL\OneDrive - TK Elevator\Documentos\chatbot_evaluation\evaluation\Lib\site-packages\requests\sessions.py", line 589, in request
    resp = self.send(prep, **send_kwargs)
  File "C:\Users\CASTILLOEMILYGABRIEL\OneDrive - TK Elevator\Documentos\chatbot_evaluation\evaluation\Lib\site-packages\requests\sessions.py", line 703, in send
    r = adapter.send(request, **kwargs)
  File "C:\Users\CASTILLOEMILYGABRIEL\OneDrive - TK Elevator\Documentos\chatbot_evaluation\evaluation\Lib\site-packages\requests\adapters.py", line 700, in send
    raise ConnectionError(e, request=request)
requests.exceptions.ConnectionError: HTTPSConnectionPool(host='tu-api-url.com', port=443): Max retries exceeded with url: /endpoint (Caused by NameResolutionError("<urllib3.connection.HTTPSConnection object at 0x0000020ED8A87A10>: Failed to resolve 'tu-api-url.com' ([Errno 11001] getaddrinfo failed)"))
